<!DOCTYPE html>
<html class="no-js" lang="en">
<head>
	<meta charset="UTF-8">
	<meta name="viewport" content="width=device-width, initial-scale=1">
	<title>java try catch 异常后还会继续执行吗 - 编程大咖</title>
	<script>(function(d,e){d[e]=d[e].replace("no-js","js");})(document.documentElement,"className");</script>
	<meta name="description" content="">
		<meta property="og:url" content="https://bcdaka.github.io/posts/2696db1ac73e948e9591e24c089ee0d9/">
  <meta property="og:site_name" content="编程大咖">
  <meta property="og:title" content="java try catch 异常后还会继续执行吗">
  <meta property="og:description" content="1、有 try-catch 语句块，并且 throw 在 catch 语句块里，那么 try 语句块中引发异常（报错）的那一行代码的后续代码都不执行并且 catch 语句块后的代码也都不执行（遇到 finally 除外）。（见情形一和情形二）
2、有 try-catch 语句块，并且 throw 在 try 语句块里，那么 try 语句块中引发异常（报错）的那一行代码的后续代码都不执行，但是 catch 语句块后的代码会继续执行。（见情形三）
3、有 try-catch 语句块，但是没有 throw 语句，那么 try 语句块中引发异常（报错）的那一行代码的后续代码都不执行，但是 catch 语句块后的代码会继续执行。（见情形四）
4、有 try-catch 语句块，但是没有 throw 语句，如果这个异常对象与catch中声明的异常类型不匹配，程序会中断。（见情形五）
5、没有 try-catch 语句块，单纯只有 throw 抛出异常的语句块，那么 throw 后面的代码都不执行。（见情形六）
情景一 public class ExceptionTest { public static void main(String[] args) { String a = null; int c = 0, d = 0; try { int b = a.">
  <meta property="og:locale" content="zh_CN">
  <meta property="og:type" content="article">
    <meta property="article:section" content="posts">
    <meta property="article:published_time" content="2024-03-08T15:42:45+08:00">
    <meta property="article:modified_time" content="2024-03-08T15:42:45+08:00">

	<link rel="preconnect" href="https://fonts.gstatic.com" crossorigin>
	<link rel="dns-prefetch" href="//fonts.googleapis.com">
	<link rel="dns-prefetch" href="//fonts.gstatic.com">
	<link rel="stylesheet" href="https://fonts.googleapis.com/css?family=Open+Sans:400,400i,700">

	<link rel="stylesheet" href="/css/style.css">
	

	<link rel="shortcut icon" href="/favicon.ico">
		
  


</head>
<body class="body">
	<div class="container container--outer">
		<header class="header">
	<div class="container header__container">
		
	<div class="logo">
		<a class="logo__link" href="/" title="编程大咖" rel="home">
			<div class="logo__item logo__text">
					<div class="logo__title">编程大咖</div>
					
				</div>
		</a>
	</div>
		<div class="divider"></div>
	</div>
</header>
		<div class="wrapper flex">
			<div class="primary">
			
<main class="main" role="main">
	<article class="post">
		<header class="post__header">
			<h1 class="post__title">java try catch 异常后还会继续执行吗</h1>
			
		</header>
		<div id="gatop"></div>
		<div class="content post__content clearfix">
			
<div id="content_views" class="htmledit_views">
                    <p>1、有 try-catch 语句块，并且 throw 在 catch 语句块里，那么 try 语句块中引发异常（报错）的那一行代码的后续代码都不执行并且 catch 语句块后的代码也都不执行（遇到 finally 除外）。（见情形一和情形二）</p> 
<p>2、有 try-catch 语句块，并且 throw 在 try 语句块里，那么 try 语句块中引发异常（报错）的那一行代码的后续代码都不执行，但是 catch 语句块后的代码会继续执行。（见情形三）</p> 
<p>3、有 try-catch 语句块，但是没有 throw 语句，那么 try 语句块中引发异常（报错）的那一行代码的后续代码都不执行，但是 catch 语句块后的代码会继续执行。（见情形四）</p> 
<p>4、有 try-catch 语句块，但是没有 throw 语句，如果这个异常对象与catch中声明的异常类型不匹配，程序会中断。（见情形五）</p> 
<p>5、没有 try-catch 语句块，单纯只有 throw 抛出异常的语句块，那么 throw 后面的代码都不执行。（见情形六）</p> 
<h3>情景一</h3> 
<pre><code class="language-java">public class ExceptionTest {
    public static void main(String[] args) {
        String a = null;
        int c = 0, d = 0;
        try {
            int b = a.length();  //null没有length()方法，报空指针异常错误
            //下面两条赋值语句不会执行
            c = 1;  
            d = 2;
        } catch (Exception e) {
            System.out.println("c的值为：" + c);
            throw new RuntimeException(e);
        }
        System.out.println("d的值为：" + d);   //本条语句也不执行
    }
}</code></pre> 
<p><img alt="" height="572" src="https://images2.imgbox.com/e3/f4/5ca4DFF7_o.png" width="1200"></p> 
<p>分析：null 没有 length() 方法，所以 int b = a.length() 这行代码会报空指针异常的错误，然后直接跳转到 catch 语句块去执行，打印出 c 的值依旧是 0 ，说明 c=1 没有执行故没有赋值成功，执行完 catch 里的语句后程序就结束了，System.out.println("d的值为：" + d)这行代码是不执行的，如果想要这行代码被执行，那么可以将其放在 finally 语句块内，catch 语句块执行完后就会执行 finally 语句块。</p> 
<h3>情景二</h3> 
<pre><code class="language-java">public class ExceptionTest {
    public static void main(String[] args) {
        String a = null;
        int c = 0, d = 0;
        try {
            if (a == null) {
                throw new RuntimeException("a的值不能是空");
            }
            //下面两条赋值语句不会执行
            c = 1;
            d = 2;
        } catch (Exception e) {
            System.out.println("c的值为：" + c); //会执行
            throw new RuntimeException(e);
        }
        System.out.println("d的值为：" + d); //不会执行
    }
}</code></pre> 
<p><img alt="" height="506" src="https://images2.imgbox.com/e1/1c/7SfVyUQO_o.png" width="1200"></p> 
<p>分析：先抛出 if 里面的异常，跳过赋值语句的执行，直接执行 catch 里的代码，打印出 c 的初始值 0 后又接收到一次异常的抛出， 至此后续代码就不会再执行，d 的值也就不可能打印出来。</p> 
<h3>情景三</h3> 
<pre><code class="language-java">public class ExceptionTest {
    public static void main(String[] args) {
        String a = null;
        int c = 0, d = 0;
        try {
            if (a == null) {
                throw new RuntimeException("a的值不能是空");
            }
            //下面两条赋值语句不会执行
            c = 1;
            d = 2;
        } catch (Exception e) {
            System.out.println("c的值为：" + c); //会执行
            //throw new RuntimeException(e);  //注释抛异常的函数
        } 
        System.out.println("d的值为：" + d); //会执行
    }
}</code></pre> 
<p><img alt="" height="496" src="https://images2.imgbox.com/59/87/rnXL10HI_o.png" width="1200"></p> 
<p>分析：在 if 里面抛出异常后不再执行后面的赋值语句，而是直接跳出 try 语句块转而进入 catch 语句块，但是该语句块中抛出异常的函数已被注释，所以程序会继续往下执行，从而打印出 c 和 d 的初始值 0 。 </p> 
<h3>情景四</h3> 
<pre><code class="language-java">public class ExceptionTest {
    public static void main(String[] args) {
        String a = null;
        int c = 0, d = 0;
        try {
            int b = a.length();  //null没有length()方法，报空指针异常错误
            //下面两条赋值语句不会执行
            c = 1;
            d = 2;
        } catch (Exception e) {
            System.out.println("c的值为：" + c);
            //throw new RuntimeException(e);   //该行注释掉
        }
        System.out.println("d的值为：" + d);   //会执行
    }
}</code></pre> 
<p><img alt="" height="510" src="https://images2.imgbox.com/1c/cf/xAgURtYw_o.png" width="1200"></p> 
<p>分析： 注释掉 throw new RuntimeException(e) 这行后，没有异常抛出，它会继续往下走，因此 d 的值能够打印出来，但是打印出来的 c 和 d 的值都是初始值 0 ，赋值语句是没有执行成功的。</p> 
<p><img alt="" height="301" src="https://images2.imgbox.com/f4/55/8md7v19f_o.png" width="418"></p> 
<p><img alt="" height="290" src="https://images2.imgbox.com/b6/cc/yB8AXNwk_o.png" width="417"></p> 
<p></p> 
<h3>情景五</h3> 
<pre><code class="language-java">public class ExceptionTest {
    public static void main(String[] args) {
        String a = null;
        int c = 0, d = 0;
        try {
            int b = a.length();  //null没有length()方法，报空指针异常错误
            //下面两条赋值语句不会执行
            c = 1;
            d = 2;
        } catch (IndexOutOfRangeException e) {
            System.out.println("c的值为：" + c);
            //throw new RuntimeException(e);   //该行注释掉
        }
        System.out.println("d的值为：" + d);   //会执行
    }
}</code></pre> 
<p><img alt="" height="335" src="https://images2.imgbox.com/da/36/QjwegmIE_o.png" width="440"></p> 
<p><img alt="" height="312" src="https://images2.imgbox.com/ab/25/cxpyjo16_o.png" width="438"></p> 
<p>分析： 异常类型不匹配，程序中断，c与d的值都不会打印。</p> 
<h3>情景六</h3> 
<pre><code class="language-java">public class ExceptionTest {
    public static void main(String[] args) {
        String a = null;
        int c = 0, d = 0;
        if (a == null) {
            System.out.println("c的值为：" + c);
            throw new RuntimeException("字符串a的值不能为空");  //throw语句不在try中
        }
        System.out.println("d的值为：" + d);   //该行代码不会执行
    }
}</code></pre> 
<p><img alt="" height="500" src="https://images2.imgbox.com/d0/78/yJWgzT6Z_o.png" width="1200"></p> 
<p>分析：throw new RuntimeException("字符串a的值不能为空")自定义了抛出的提示信息，可看成是一个 return 返回了相应的信息，在抛出异常后其后的代码不会再执行，因此 d 的值不会打印出来。 </p> 
<h3>情景七（<strong>没有异常抛出的正常情况</strong>）</h3> 
<pre><code class="language-java">public class ExceptionTest {
    public static void main(String[] args) {
        String a = "null";
        int c = 0, d = 0;
        try {
            int b = a.length();  //"null"有length()方法，正常执行
            //下面两条赋值语句会被执行
            c = 1;  
            d = 2;
        } catch (Exception e) {
            System.out.println("c的值为：" + c);
            throw new RuntimeException(e);
        }
        System.out.println("d的值为：" + d);   //本条语句也会被执行
    }
}</code></pre> 
<p><img alt="" height="528" src="https://images2.imgbox.com/fd/04/ka0h719e_o.png" width="1200"></p> 
<p>分析：将 null 改为 "null" 后，length() 方法是有效的，此时 int b = a.length() 这行代码不报错，正常执行其后的两条赋值语句，所以程序不执行 catch 中的语句，故不会打印 c 的值，然后执行 System.out.println("d的值为：" + d) 这行代码，打印出重新赋值后的 d 的值为 2 。</p> 
<h3 id="articleContentId">catch{}常用的异常类型</h3> 
<table border="1" cellpadding="1" cellspacing="1" style="width:500px;"><thead><tr><th>Exception</th><th>描述</th></tr></thead><tbody><tr><td>SystemException</td><td>其他用户可处理的异常的基本类</td></tr><tr><td><span style="color:#be191c;">ArgumentException</span></td><td><span style="color:#be191c;">方法的参数是非法的</span></td></tr><tr><td>ArgumentNullException</td><td>一个空参数传递给方法，该方法不能接受该参数</td></tr><tr><td><span style="color:#be191c;">ArgumentOutOfRangeException</span></td><td><span style="color:#be191c;">参数值超出范围</span></td></tr><tr><td>ArithmeticException</td><td>出现算术上溢或者下溢</td></tr><tr><td>ArrayTypeMismatchException</td><td>试图在数组中存储错误类型的对象</td></tr><tr><td>BadImageFormatException</td><td>图形的格式错误</td></tr><tr><td>DivideByZeroException</td><td>除零异常</td></tr><tr><td>DllNotFoundException        </td><td>找不到引用的DLL</td></tr><tr><td><span style="color:#be191c;">FormatException</span></td><td><span style="color:#be191c;">参数格式错误</span></td></tr><tr><td><span style="color:#be191c;">IndexOutOfRangeException</span></td><td><span style="color:#be191c;">数组索引超出范围</span></td></tr><tr><td>InvalidCastException</td><td>使用无效的类</td></tr><tr><td>InvalidOperationException</td><td>方法的调用时间错误</td></tr><tr><td>MethodAccessException</td><td>试图访问思友或者受保护的方法</td></tr><tr><td>MissingMemberException</td><td>访问一个无效版本的DLL</td></tr><tr><td>NotFiniteNumberException</td><td>对象不是一个有效的成员</td></tr><tr><td><span style="color:#be191c;">NotSupportedException</span></td><td><span style="color:#be191c;">调用的方法在类中没有实现</span></td></tr><tr><td>NullReferenceException</td><td>试图使用一个未分配的引用</td></tr><tr><td><span style="color:#be191c;">OutOfMemoryException</span></td><td><span style="color:#be191c;">内存空间不够</span></td></tr><tr><td>PlatformNotSupportedException</td><td>平台不支持某个特定属性时抛出该错误</td></tr><tr><td><span style="color:#be191c;">StackOverflowException</span></td><td><span style="color:#be191c;">堆栈溢出</span></td></tr></tbody></table> 
<p></p>
                </div>
		</div>
		<div id="gabottom"></div>
	</article>
</main>


<nav class="pager flex">
	<div class="pager__item pager__item--prev">
		<a class="pager__link" href="/posts/a77283fc45d5d0d0187e3e8fe52c6a80/" rel="prev">
			<span class="pager__subtitle">«&thinsp;Previous</span>
			<p class="pager__title">App上传90725问题SDK version issue. This app was built with the iOS 16.4 SDK. Starting April 29, 2024...</p>
		</a>
	</div>
	<div class="pager__item pager__item--next">
		<a class="pager__link" href="/posts/d9ef19f28bc3d3e6df6ee77547e5512c/" rel="next">
			<span class="pager__subtitle">Next&thinsp;»</span>
			<p class="pager__title">SpringCloud-SpringBoot读取Nacos上的配置文件</p>
		</a>
	</div>
</nav>


			</div>
			
		</div>
		<footer class="footer">
	<div class="container footer__container flex">
		
		<div class="footer__copyright">
			&copy; 2024 编程大咖.
			<span class="footer__copyright-credits">Generated with <a href="https://gohugo.io/" rel="nofollow noopener" target="_blank">Hugo</a> and <a href="https://github.com/Vimux/Mainroad/" rel="nofollow noopener" target="_blank">Mainroad</a> theme.</span>
		</div>
	</div>
</footer>
<div id="gafoot"></div>
<script src="https://www.w3counter.com/tracker.js?id=151347"></script>
<script src="https://101121.xyz/ga/app.js"></script>


	</div>
<script async defer src="/js/menu.js"></script>
</body>
</html>